Workbook

Sheet Sector Wise Analysis
A2: Total A/Cs | F2: Overall | L2: Closed/C4 | R2: Pipeline
A3: Status | B3: A/Cs | C3: Expexted Revenue | F3: Industry | G3: Status | H3: A/Cs | I3: Expexted Revenue | L3: Industry | M3: Status | N3: A/Cs | O3: Expected Revenue | R3: Industry | S3: Status | T3: A/Cs | U3: Expected Revenue
A4: Cancelled | B4: 983 | C4: 50034494 | F4: Agritech | H4: 14 | I4: 333000 | L4: Grand Total | R4: Grand Total | X4: Analysis
A5: Grand Total | B5: 983 | C5: 50034494 | F5: Automobile | H5: 18 | I5: 283000
F6: Banking Finance & Insurance | H6: 53 | I6: 2006000
F7: Community | H7: 19 | I7: 1627000
F8: Defence & Aerospace | H8: 8 | I8: 1323000
F9: Distributers | H9: 11 | I9: 309000
F10: Education | H10: 173 | I10: 4758009
F11: Entertainment | H11: 7 | I11: 950000
F12: Events | H12: 35 | I12: 1594000
F13: F&B | G13: Cancelled | H13: 2 | I13: 98000
F14: F&B Total | H14: 2 | I14: 98000
F15: Family Group | H15: 83 | I15: 3856363
F16: FMCG | H16: 14 | I16: 1745000
F17: Healthcare | H17: 26 | I17: 447000
F18: IT | H18: 250 | I18: 7546392
F19: Manufacturing | H19: 35 | I19: 1233800
F20: Pharma | H20: 51 | I20: 1555000
F21: Realestate | H21: 23 | I21: 1098000
F22: Retail | H22: 26 | I22: 1337000
F23: Sports | H23: 7 | I23: 950000
F24: Tourism | H24: 44 | I24: 1144950
F25: Transport | H25: 7 | I25: 170000
... F34: Grand Total | H34: 976 | I34: 48704494

Sheet Detail1
A1: Details for Sum of Expected Business - Expected Business Month: 10/1/2025
A3: Date | B3: A/C Name | C3: Connect Status | D3: TYPE | E3: Industry | F3: Spoc Name | G3: Conversation | H3: Expected Business | I3: Actual Closed Business | J3: Expected Business Month | K3: Region | L3: Status | M3: Lead Status | N3: Reason | O3: Expected sales of Haleem | P3: Type Of Business | Q3: Punched Date | R3: 1st meeting Date | S3: Month | T3: Week | U3: Year
A4: 45912 | B4: Azad Engineering | C4: F2F | D4: Corporate | E4: Manufacturing | F4: Bharat/Badulla | G4: Delivery of Gift Vouchers for employees | H4: 2150000 | I4: 2150000 | J4: 45931 | K4: Hyderabad | L4: Closed(C4) | M4: Closed | O4: 0 | P4: Bulk Order | S4: Sep-25 | T4: 37
A5: 45939 | B5: AO Production | C5: F2F | D5: Corporate | E5: Tourism | F5: Srinivas | G5: Dine in at Shamshabad & Imax on 12-10-2025 | H5: 216348 | I5: 216348 | J5: 45931 | K5: Hyderabad | L5: Closed(C4) | M5: Closed | O5: 0 | P5: Bulk Order | S5: Oct-25 | T5: 41
A6: 45939 | B6: Cube Highways | C6: F2F | D6: Corporate | E6: Realestate | F6: Saikiran | G6: Shared details of Buffet lunch on 16-9-2025 160017 | H6: 161700 | I6: 161700 | J6: 45931 | K6: Hyderabad | L6: Closed(C4) | M6: Closed | O6: 0 | P6: Bulk Order | S6: Oct-25 | T6: 41
A7: 45929 | B7: Intercity Transport Logistics | C7: F2F | D7: Corporate | E7: IT | F7: Mallikarjuna | G7: Payment followup and delivery on 1-10-2025 | H7: 63000 | I7: 63000 | J7: 45931 | K7: Hyderabad | L7: Closed(C4) | M7: Closed | O7: 0 | P7: Bulk Order | S7: Sep-25 | T7: 40
A8: 45944 | B8: Platos | C8: F2F | D8: Corporate | E8: F&B Agrigator | F8: Hyder | G8: Delivery of employee lunch on 14-10-2025 | H8: 58185 | I8: 58185 | J8: 45931 | K8: Hyderabad | L8: Closed(C4) | M8: Closed | O8: 0 | P8: Bulk Order | S8: Oct-25 | T8: 42
A9: 45937 | B9: Accenture | C9: F2F | D9: Corporate | E9: IT | F9: Sasidevi | G9: Popup of at Accenture on 7-10-2025 | H9: 47590 | I9: 47590 | J9: 45931 | K9: Hyderabad | L9: Closed(C4) | M9: Closed | O9: 0 | P9: Bulk Order | S9: Oct-25 | T9: 41
A10: 45961 | B10: Anthea Pharma | C10: F2F | D10: Corporate | E10: Pharma | F10: Jaipal | G10: Take away from Muthangi Store in October Month | H10: 44825 | I10: 44825 | J10: 45931 | K10: Hyderabad | L10: Closed(C4) | M10: Closed | O10: 0 | P10: Bulk Order | S10: Oct-25 | T10: 44
A11: 45945 | B11: Platos | C11: F2F | D11: Corporate | E11: F&B Agrigator | F11: Hyder | G11: Delivery of employee lunch on 15-10-2025 | H11: 43200 | I11: 43200 | J11: 45931 | K11: Hyderabad | L11: Closed(C4) | M11: Closed | O11: 0 | P11: Bulk Order | S11: Oct-25 | T11: 42
A12: 45946 | B12: Platos | C12: F2F | D12: Corporate | E12: F&B Agrigator | F12: Hyder | G12: Delivery of employee lunch on 16-10-2025 | H12: 40905 | I12: 40905 | J12: 45931 | K12: Hyderabad | L12: Closed(C4) | M12: Closed | O12: 0 | P12: Bulk Order | S12: Oct-25 | T12: 42
A13: 45943 | B13: Platos | C13: F2F | D13: Corporate | E13: F&B Agrigator | F13: Rohan | G13: Delivery of employee lunch on 13-10-2025 | H13: 39555 | I13: 39555 | J13: 45931 | K13: Hyderabad | L13: Closed(C4) | M13: Closed | O13: 0 | P13: Bulk Order | S13: Oct-25 | T13: 42
A14: 45952 | B14: Delivery at SEBLR Banglore (Compass) | C14: Call | D14: Corporate | E14: F&B Agrigator | F14: Saad | G14: New Delivery at Compass group on 22-10-2025 | H14: 39416 | I14: 39416 | J14: 45931 | K14: Bangalore | L14: Closed(C4) | M14: Closed | O14: 0 | P14: Bulk Order | S14: Oct-25 | T14: 43
A15: 45959 | B15: Delivery at SEBLR Banglore (Compass) | C15: Call | D15: Corporate | E15: F&B Agrigator | F15: Saad | G15: New Delivery at Compass group on 29-10-2025 | H15: 38040 | I15: 38040 | J15: 45931 | K15: Bangalore | L15: Closed(C4) | M15: Closed | O15: 0 | P15: Bulk Order | S15: Oct-25 | T15: 44
... A60: 45930 | B60: Intercity Transport Logistics | C60: F2F | D60: Corporate | E60: IT | F60: Mallikarjuna | G60: Confirmation of delivery 3 location on 1-10-2025 | H60: 0 | I60: 0 | J60: 45931 | K60: Hyderabad | L60: Closed(C4) | M60: Closed | O60: 0 | P60: Bulk Order | S60: Sep-25 | T60: 40
A61: 45925 | B61: Accenture | C61: F2F | D61: Corporate | E61: IT | F61: Afroz | G61: ODC in October | H61: 0 | J61: 45931 | K61: Hyderabad | L61: Closed(C4) | M61: Closed | O61: 0 | P61: Corporate Order | S61: Sep-25 | T61: 39

Sheet Detail2
A1: Details for Sum of Expected Business - Expected Business Month: 9/1/2025
A3: Date | B3: A/C Name | C3: Connect Status | D3: TYPE | E3: Industry | F3: Spoc Name | G3: Conversation | H3: Expected Business | I3: Actual Closed Business | J3: Expected Business Month | K3: Region | L3: Status | M3: Lead Status | N3: Reason | O3: Expected sales of Haleem | P3: Type Of Business | Q3: Punched Date | R3: 1st meeting Date | S3: Month | T3: Week | U3: Year
A4: 45930 | B4: Popup Counter at Capital Land Block A | C4: Call | D4: Corporate | E4: F&B Agrigator | F4: Vamsi | G4: Sale of CB,VB,MB,DKM on 29-9-2025 | H4: 9550 | I4: 9550 | J4: 45901 | K4: Hyderabad | L4: Closed(C4) | M4: Closed | O4: 0 | P4: Corporate Order | S4: Sep-25 | T4: 40
A5: 45930 | B5: IIT Hyderabad | C5: Call | D5: College | E5: Education | F5: Mohan | G5: Biryani popup counter on 30-9-2024 | H5: 12500 | I5: 12500 | J5: 45901 | K5: Hyderabad | L5: Closed(C4) | M5: Closed | O5: 0 | P5: Corporate Order | S5: Sep-25 | T5: 40
A6: 45929 | B6: Anthea Pharma | C6: F2F | D6: Corporate | E6: Pharma | F6: Jaipal | G6: Take away of CB & VB in September month | H6: 20500 | I6: 20500 | J6: 45901 | K6: Hyderabad | L6: Closed(C4) | M6: Closed | O6: 0 | P6: Corporate Order | S6: Sep-25 | T6: 40
A7: 45929 | B7: Popup Counter at Capital Land Block A | C7: Call | D7: Corporate | E7: F&B Agrigator | F7: Vamsi | G7: Sale of CB,VB,MB,DKM on 29-9-2025 | H7: 10267 | I7: 10267 | J7: 45901 | K7: Hyderabad | L7: Closed(C4) | M7: Closed | O7: 0 | P7: Corporate Order | S7: Sep-25 | T7: 40
A8: 45929 | B8: IIT Hyderabad | C8: Call | D8: College | E8: Education | F8: Mohan | G8: Biryani popup counter on 29-9-2024 | H8: 16500 | I8: 16500 | J8: 45901 | K8: Hyderabad | L8: Closed(C4) | M8: Closed | O8: 0 | P8: Corporate Order | S8: Sep-25 | T8: 40
A9: 45928 | B9: Intercity Transport Logistics | C9: F2F | D9: Corporate | E9: IT | F9: Mallikarjuna | G9: Dusshera Lunch for 700 on 28-09-2025 | H9: 199120 | I9: 199120 | J9: 45901 | K9: Hyderabad | L9: Closed(C4) | M9: Closed | O9: 0 | P9: Bulk Order | S9: Sep-25 | T9: 39
A10: 45928 | B10: IIT Hyderabad | C10: Call | D10: College | E10: Education | F10: Mohan | G10: Biryani popup counter on 27-9-2024 | H10: 6500 | I10: 6500 | J10: 45901 | K10: Hyderabad | L10: Closed(C4) | M10: Closed | O10: 0 | P10: Corporate Order | S10: Sep-25 | T10: 39
A11: 45927 | B11: IIT Hyderabad | C11: Call | D11: College | E11: Education | F11: Mohan | G11: Biryani popup counter on 27-9-2024 | H11: 14000 | I11: 14000 | J11: 45901 | K11: Hyderabad | L11: Closed(C4) | M11: Closed | O11: 0 | P11: Corporate Order | S11: Sep-25 | T11: 39
A12: 45926 | B12: Axix Securities | C12: F2F | D12: Corporate | E12: Banking Finance & Insurance | F12: Nilesh | G12: Delivery of VB & Kabab on 29-9-2025 | H12: 11200 | I12: 11200 | J12: 45901 | K12: Hyderabad | L12: Closed(C4) | M12: Closed | O12: 0 | P12: Corporate Order | S12: Sep-25 | T12: 39
A13: 45926 | B13: Popup Counter at Capital Land Block A | C13: F2F | D13: Corporate | E13: F&B Agrigator | F13: Vamsi | G13: Sale of CB,VB,MB,DKM on 26-9-2025 | H13: 18330 | I13: 18330 | J13: 45901 | K13: Hyderabad | L13: Closed(C4) | M13: Closed | O13: 0 | P13: Corporate Order | S13: Sep-25 | T13: 39
A14: 45926 | B14: IIT Hyderabad | C14: Call | D14: College | E14: Education | F14: Mohan | G14: Biryani popup counter on 26-9-2024 | H14: 15000 | I14: 15000 | J14: 45901 | K14: Hyderabad | L14: Closed(C4) | M14: Closed | O14: 0 | P14: Corporate Order | S14: Sep-25 | T14: 39
A15: 45925 | B15: Popup Counter at Capital Land Block A | C15: F2F | D15: Corporate | E15: F&B Agrigator | F15: Vamsi | G15: Sale of CB,VB,MB,DKM on 25-9-2025 | H15: 18330 | I15: 18330 | J15: 45901 | K15: Hyderabad | L15: Closed(C4) | M15: Closed | O15: 0 | P15: Corporate Order | S15: Sep-25 | T15: 39
... A75: 45895 | B75: Delivery at Medchal Farm house | C75: Call | D75: Corporate | E75: Manufacturing | F75: Anudeep | G75: Delivery of food in Sepetmber | H75: 0 | I75: 0 | J75: 45901 | K75: Hyderabad | L75: Closed(C4) | M75: Closed | O75: 0 | P75: Corporate Order | S75: Aug-25 | T75: 35
A76: 45824 | B76: Hive Space | C76: F2F | D76: Corporate | E76: IT | F76: Mallikarjuna | G76: follow up for delivery of food at their office | H76: 0 | I76: 0 | J76: 45901 | K76: Hyderabad | L76: Closed(C4) | M76: Closed | O76: 0 | P76: Corporate Order | S76: Jun-25 | T76: 25 | U76: 2025
A77: 45817 | B77: IIT Hyderabad | C77: Call | D77: College | E77: Education | F77: Abanik | G77: Follow up for bulk orders | H77: 0 | J77: 45901 | K77: Hyderabad | L77: Closed(C4) | M77: Closed | O77: 0 | P77: Corporate Order | S77: Jun-25 | T77: 24 | U77: 2025
A78: 45894 | B78: Anthea Pharma | C78: F2F | D78: Corporate | E78: Pharma | F78: Jaipal | G78: monthly food requirement with B to C | H78: 0 | I78: 0 | J78: 45901 | K78: Hyderabad | L78: Negotiation(C2) | M78: Hot | O78: 0 | P78: Corporate Order | S78: Aug-25 | T78: 35
A79: 45867 | B79: The Gratitude lane | C79: Call | D79: Corporate | E79: Gifting | F79: Abhinav | G79: Shared details of Biryani kit for gifting | J79: 45901 | K79: Hyderabad | L79: Negotiation(C2) | M79: Hot | O79: 0 | P79: Corporate Order | S79: Jul-25 | T79: 31

Sheet Detail3
A1: Details for Sum of Expected Business - Expected Business Month: 8/1/2025
A3: Date | B3: A/C Name | C3: Connect Status | D3: TYPE | E3: Industry | F3: Spoc Name | G3: Conversation | H3: Expected Business | I3: Actual Closed Business | J3: Expected Business Month | K3: Region | L3: Status | M3: Lead Status | N3: Reason | O3: Expected sales of Haleem | P3: Type Of Business | Q3: Punched Date | R3: 1st meeting Date | S3: Month | T3: Week | U3: Year
A4: 45898 | B4: Popup Counter at Capital Land Block A | C4: Call | D4: Corporate | E4: F&B Agrigator | F4: Vamsi | G4: Sale of CB,VB,MB,DKM on 29-8-2025 | H4: 19200 | I4: 19200 | J4: 45870 | K4: Hyderabad | L4: Closed(C4) | M4: Closed | O4: 0 | S4: Aug-25 | T4: 35
A5: 45897 | B5: Delivery at Bowenpally | C5: F2F | D5: Event | E5: Family Group | F5: Sreeramlu | G5: Delivery of CB on 31-8-2025 | H5: 12000 | J5: 45870 | K5: Hyderabad | L5: Closed(C4) | M5: Closed | O5: 0 | S5: Aug-25 | T5: 35
A6: 45897 | B6: Popup Counter at Capital Land Block A | C6: Call | D6: Corporate | E6: F&B Agrigator | F6: Vamsi | G6: Sale of CB,VB,MB,DKM on 28-8-2025 | H6: 18552 | I6: 18552 | J6: 45870 | K6: Hyderabad | L6: Closed(C4) | M6: Closed | O6: 0 | S6: Aug-25 | T6: 35
A7: 45895 | B7: Popup Counter at Capital Land Block A | C7: Call | D7: Corporate | E7: F&B Agrigator | F7: Vamsi | G7: Sale of CB,VB,MB,DKM on 26-8-2025 | H7: 19461 | I7: 19461 | J7: 45870 | K7: Hyderabad | L7: Closed(C4) | M7: Closed | O7: 0 | S7: Aug-25 | T7: 35
A8: 45894 | B8: Medtronics | C8: F2F | D8: Corporate | E8: Pharma | F8: Asad | G8: combo delivery on 29-8-2025 at Vizag and Panjagutta | H8: 30000 | J8: 45870 | K8: Hyderabad | L8: Closed(C4) | M8: Closed | O8: 0 | S8: Aug-25 | T8: 35
A9: 45894 | B9: Delivery at SEBLR Banglore (Compass) | C9: Call | D9: Corporate | E9: F&B Agrigator | F9: Saad | G9: New Delivery at Compass group on 25-8-2025 | H9: 51569 | I9: 51569 | J9: 45870 | K9: Bangalore | L9: Closed(C4) | M9: Closed | O9: 0 | S9: Aug-25 | T9: 35
A10: 45894 | B10: Popup Counter at Capital Land Block A | C10: Call | D10: Corporate | E10: F&B Agrigator | F10: Vamsi | G10: Sale of CB,VB,MB,DKM on 25-8-2025 | H10: 17487 | I10: 17487 | J10: 45870 | K10: Hyderabad | L10: Closed(C4) | M10: Closed | O10: 0 | S10: Aug-25 | T10: 35
A11: 45891 | B11: Destination World Holidays | C11: F2F | D11: Corporate | E11: Tourism | F11: Saltanat | G11: Lunch at Charminar on 25/8/2025 | H11: 35000 | I11: 35000 | J11: 45870 | K11: Hyderabad | L11: Closed(C4) | M11: Closed | O11: 0 | S11: Aug-25 | T11: 34
A12: 45891 | B12: Popup Counter at Capital Land Block A | C12: Call | D12: Corporate | E12: F&B Agrigator | F12: Vamsi | G12: Sale of CB,VB,MB,DKM on 22-8-2025 | H12: 13546 | I12: 13546 | J12: 45870 | K12: Hyderabad | L12: Closed(C4) | M12: Closed | O12: 0 | S12: Aug-25 | T12: 34
A13: 45890 | B13: Popup Counter at Capital Land Block A | C13: Call | D13: Corporate | E13: F&B Agrigator | F13: Vamsi | G13: Sale of CB,VB,MB,DKM on 21-8-2025 | H13: 20650 | I13: 20650 | J13: 45870 | K13: Hyderabad | L13: Closed(C4) | M13: Closed | O13: 0 | S13: Aug-25 | T13: 34
A14: 45889 | B14: GHMC Group | C14: Call | D14: Corporate | E14: Government | F14: Venkat Nagendra | G14: Dine in at secbad on 20-8-2025 | H14: 22352 | I14: 22352 | J14: 45870 | K14: Hyderabad | L14: Closed(C4) | M14: Closed | O14: 0 | S14: Aug-25 | T14: 34
A15: 45889 | B15: Delivery at SEBLR Banglore (Compass) | C15: Call | D15: Corporate | E15: F&B Agrigator | F15: Saad | G15: New Delivery at Compass group on 20-8-2025 | H15: 65725 | I15: 65725 | J15: 45870 | K15: Bangalore | L15: Closed(C4) | M15: Closed | O15: 0 | S15: Aug-25 | T15: 34
A16: 45889 | B16: Delivery at Compass Group Bangalore | C16: Call | D16: Corporate | E16: F&B Agrigator | F16: Pankaj | G16: Delivery of Special CB & MB Handi on 13-8-2020 | H16: 59544 | I16: 59544 | J16: 45870 | K16: Bangalore | L16: Closed(C4) | M16: Closed | O16: 0 | S16: Aug-25 | T16: 34
A17: 45889 | B17: Gokhana | C17: F2F | D17: Corporate | E17: F&B Agregator | F17: Sandhya | G17: Restart of Popup countar at Capital Land | H17: 0 | I17: 0 | J17: 45870 | K17: Hyderabad | L17: Closed(C4) | M17: Closed | O17: 0 | S17: Aug-25 | T17: 34
A18: 45886 | B18: Delivery at Secundrabad | C18: Call | D18: Events | E18: Family Group | F18: Apoorva | G18: Delivery of CB & VB at Secundrabad | H18: 9500 | I18: 9500 | J18: 45870 | K18: Hyderabad | L18: Closed(C4) | M18: Closed | O18: 0 | S18: Aug-25 | T18: 33
A19: 45886 | B19: Dine in at Vanasthalipuram | C19: Call | D19: Events | E19: Family Group | F19: Arun | G19: Dine in at Vanasthalipuram on 17-8-2025 | H19: 4344 | I19: 4344 | J19: 45870 | K19: Hyderabad | L19: Closed(C4) | M19: Closed | O19: 0 | S19: Aug-25 | T19: 33
A20: 45884 | B20: Delivery at Malkajgiri | C20: Call | D20: Corporate | E20: Manufacturing | F20: Ajay | G20: Delivery of CB at Malkajgiri on 15-8-2025 | H20: 21795 | I20: 21795 | J20: 45870 | K20: Hyderabad | L20: Closed(C4) | M20: Closed | O20: 0 | S20: Aug-25 | T20: 33
... A44: 45870 | B44: Delivery at Malkajgiri | C44: Call | D44: Events | E44: Family Group | F44: Mukesh | G44: Deli | H44: 8119 | I44: 8119 | J44: 45870 | K44: Hyderabad | L44: Closed(C4) | M44: Closed | O44: 0 | S44: Aug-25 | T44: 31
A45: 45868 | B45: Delivery of Veg Biryani at Secundrabad | C45: Call | D45: Events | E45: Family Group | F45: Vijay | G45: Delivery of VB on 1-8-2025 | H45: 9000 | J45: 45870 | K45: Hyderabad | L45: Closed(C4) | M45: Hot | O45: 0 | S45: Jul-25 | T45: 31
A46: 45867 | B46: Birthday Party at Kukatpally | C46: F2F | D46: Events | E46: Family Group | F46: Kavita | G46: Shared buffet and location detail party on 15-8-2025 | H46: 28000 | I46: 28000 | J46: 45870 | K46: Hyderabad | L46: Closed(C4) | M46: Closed | O46: 0 | S46: Jul-25 | T46: 31
A47: 45845 | B47: MSN Labs | C47: F2F | D47: Corporate | E47: Pharma | F47: Sandeep | G47: Follow up for payments | H47: 0 | I47: 0 | J47: 45870 | K47: Hyderabad | L47: Closed(C4) | M47: Closed | O47: 0 | S47: Jul-25 | T47: 28 | U47: 2025
B69: 45785 | C69: 4207000
B70: 45798 | C70: 4207000
B71: 45958 | C71: 7599375
B72: 45989 | C72: 2086875

Sheet Detail4
A1: Details for Sum of Expected Business - Expected Business Month: 3/1/2026
A3: Date | B3: A/C Name | C3: Connect Status | D3: TYPE | E3: Industry | F3: Spoc Name | G3: Conversation | H3: Expected Business | I3: Actual Closed Business | J3: Expected Business Month | K3: Region | L3: Status | M3: Lead Status | N3: Reason | O3: Expected sales of Haleem | P3: Type Of Business | Q3: Punched Date | R3: 1st meeting Date | S3: Month | T3: Week | U3: Year
A4: 46112 | B4: Cognizant GAR ( Smart Q ) | C4: F2F | D4: Corporate | E4: IT | F4: Samruddhi | G4: Popup on 31-3-2026 | H4: 39800 | I4: 39800 | J4: 46082 | K4: Hyderabad | L4: Closed(C4) | M4: Closed | O4: 0 | P4: Popup | S4: Mar-26 | T4: 14
A5: 46112 | B5: EA Sports (Compass) | C5: F2F | D5: Corporate | E5: IT | F5: Sandeep | G5: Popup on 31-3-2026 Gachibowli | H5: 115000 | I5: 115000 | J5: 46082 | K5: Hyderabad | L5: Closed(C4) | M5: Closed | O5: 0 | P5: Popup | S5: Mar-26 | T5: 14
A6: 46112 | B6: Deloitte Towers (Hungerbox) | C6: F2F | D6: Corporate | E6: IT | F6: Rajender | G6: Popup from BHEL on 30-3-2026 | H6: 66650 | I6: 66650 | J6: 46082 | K6: Hyderabad | L6: Closed(C4) | M6: Closed | O6: 0 | P6: Popup | S6: Mar-26 | T6: 14
A7: 46112 | B7: Accenture HDC2 (Hungerbox) | C7: Call | D7: Corporate | E7: IT | F7: Praveen | G7: Haleem popup 31-03-2026 Gudimalkapur | H7: 10200 | I7: 10200 | J7: 46082 | K7: Hyderabad | L7: Closed(C4) | M7: Closed | O7: 0 | P7: Popup | S7: Mar-26 | T7: 14
A8: 46111 | B8: Deloitte Towers (Hungerbox) | C8: F2F | D8: Corporate | E8: IT | F8: Rajender | G8: Popup from BHEL on 30-3-2026 | H8: 42780 | I8: 42780 | J8: 46082 | K8: Hyderabad | L8: Closed(C4) | M8: Closed | O8: 0 | P8: Popup | S8: Mar-26 | T8: 14
A9: 46111 | B9: Accenture HDC2 (Hungerbox) | C9: Call | D9: Corporate | E9: IT | F9: Praveen | G9: Haleem popup 30-03-2026 Gudimalkapur | H9: 8700 | I9: 8700 | J9: 46082 | K9: Hyderabad | L9: Closed(C4) | M9: Closed | O9: 8700 | P9: Popup | S9: Mar-26 | T9: 14
A10: 46110 | B10: Dine in at Secundrabad | C10: Call | D10: Events | E10: Family Group | F10: Arun | G10: Dine in Secundrabad on 29-3-2026 | H10: 18500 | I10: 18500 | J10: 46082 | K10: Hyderabad | L10: Closed(C4) | M10: Closed | O10: 0 | P10: Bulk Order | S10: Mar-26 | T10: 13
A11: 46109 | B11: Dine in at IMAX | C11: Call | D11: Events | E11: Family Group | F11: Sirish | G11: Dine in IMAX in 28-3-2026 | H11: 6500 | I11: 6500 | J11: 46082 | K11: Hyderabad | L11: Closed(C4) | M11: Closed | O11: 0 | P11: Bulk Order | S11: Mar-26 | T11: 13
A12: 46108 | B12: Cognizant Mindspace 20B | C12: Call | D12: Corporate | E12: IT | F12: Mohan | G12: Haleem Popup on 27-3-2026 Gachibowli | H12: 9175 | I12: 9175 | J12: 46082 | K12: Hyderabad | L12: Closed(C4) | M12: Closed | O12: 9175 | P12: Popup | S12: Mar-26 | T12: 13
A13: 46108 | B13: Cognizant Mindspace 12A | C13: Call | D13: Corporate | E13: IT | F13: Mohan | G13: Haleem Popup on 27-3-2026 Gachibowli | H13: 21413 | I13: 21413 | J13: 46082 | K13: Hyderabad | L13: Closed(C4) | M13: Closed | O13: 21413 | P13: Popup | S13: Mar-26 | T13: 13
A14: 46108 | B14: Cognizant Pheonix SEZ | C14: Call | D14: Corporate | E14: IT | F14: Vikash | G14: Haleem Popup on 27-3-2026 Sarath City | H14: 16430 | I14: 16430 | J14: 46082 | K14: Hyderabad | L14: Closed(C4) | M14: Closed | O14: 16430 | P14: Popup | S14: Mar-26 | T14: 13
A15: 46108 | B15: Accenture HDC3 (Hungerbox) | C15: Call | D15: Corporate | E15: IT | F15: Pawan | G15: Haleem popup 26-03-2026 BHEL | H15: 48160 | I15: 48160 | J15: 46082 | K15: Hyderabad | L15: Closed(C4) | M15: Closed | O15: 48160 | P15: Popup | S15: Mar-26 | T15: 13
... A125: 46083 | B125: Haleem Counter at Infosys Pocharam | C125: Call | D125: Corporate | E125: IT | F125: Sathya | G125: Haleem popup on 02-03-2026 | H125: 8571 | I125: 8571 | J125: 46082 | K125: Hyderabad | L125: Closed(C4) | M125: Closed | O125: 8571 | P125: Popup | S125: Mar-26 | T125: 10

Sheet Overall Sales
A2: Sales Region wise
A3: Expected Business | B3: Month
B4: Bangalore | X4: Bangalore Total | Y4: Hyderabad | AY4: Hyderabad Total | AZ4: Grand Total
A5: Status | B5: 45292 | C5: 45323 | D5: 45352 | E5: 45383 | F5: 45413 | G5: 45444 | H5: 45474 | I5: 45505 | J5: 45536 | K5: 45566 | L5: 45597 | M5: 45627 | N5: 45658 | O5: 45689 | P5: 45717 | Q5: 45748 | R5: 45778 | S5: 45809 | T5: 45839 | U5: 45870 | V5: 45901 | W5: 45931 | Y5: 45231 | Z5: 45261 | AA5: 45292 | AB5: 45323 | AC5: 45352 | AD5: 45383 | AE5: 45413 | AF5: 45444 | AG5: 45474 | AH5: 45505 | AI5: 45536 | AJ5: 45566 | AK5: 45597 | AL5: 45627 | AM5: 45658 | AN5: 45689 | AO5: 45717 | AP5: 45748 | AQ5: 45778 | AR5: 45809 | AS5: 45839 | AT5: 45870 | AU5: 45901 | AV5: 45931 | AW5: 45962 | AX5: 45992
A6: Closed(C4) | B6: 244671 | C6: 184184 | D6: 672620 | E6: 630993 | F6: 224623 | G6: 177151 | H6: 357305 | I6: 172060 | J6: 173396 | K6: 36855 | L6: 175565 | M6: 139607 | N6: 158594 | O6: 192091 | P6: 137347 | Q6: 190048 | R6: 246746 | S6: 188839 | T6: 381506 | U6: 430226 | V6: 132965 | W6: 130236 | X6: 5377628 | Y6: 216000 | Z6: 441884 | AA6: 628380 | AB6: 490291 | AC6: 867317 | AD6: 555748 | AE6: 2786000 | AF6: 3048664 | AG6: 597840 | AH6: 2140563 | AI6: 430500 | AJ6: 3443777 | AK6: 6653985 | AL6: 4745972 | AM6: 4074521 | AN6: 1515634 | AO6: 1889599 | AP6: 1900919 | AQ6: 735453 | AR6: 420218 | AS6: 8804468 | AT6: 597307 | AU6: 1929384 | AV6: 3303210 | AW6: 7599375 | AX6: 3224730 | AY6: 63041739 | AZ6: 68419367
A7: Negotiation(C2) | B7: 0 | C7: 0 | D7: 0 | E7: 0 | F7: 0 | G7: 0 | H7: 0 | I7: 0 | J7: 0 | K7: 0 | L7: 0 | M7: 0 | N7: 0 | O7: 0 | P7: 0 | Q7: 0 | R7: 0 | S7: 0 | T7: 0 | U7: 0 | V7: 0 | W7: 0 | X7: 0 | Y7: 0 | Z7: 0 | AA7: 0 | AB7: 0 | AC7: 0 | AD7: 0 | AE7: 0 | AF7: 0 | AG7: 0 | AH7: 0 | AI7: 0 | AJ7: 0 | AK7: 0 | AL7: 0 | AM7: 0 | AN7: 0 | AO7: 0 | AP7: 0 | AQ7: 0 | AR7: 0 | AS7: 0 | AT7: 0 | AU7: 0 | AV7: 0 | AW7: 0 | AX7: 0 | AY7: 0 | AZ7: 0
A8: Grand Total | B8: 244671 | C8: 184184 | D8: 672620 | E8: 630993 | F8: 224623 | G8: 177151 | H8: 357305 | I8: 172060 | J8: 173396 | K8: 36855 | L8: 175565 | M8: 139607 | N8: 158594 | O8: 192091 | P8: 137347 | Q8: 190048 | R8: 246746 | S8: 188839 | T8: 381506 | U8: 430226 | V8: 132965 | W8: 130236 | X8: 5377628 | Y8: 216000 | Z8: 441884 | AA8: 628380 | AB8: 490291 | AC8: 867317 | AD8: 555748 | AE8: 2786000 | AF8: 3048664 | AG8: 597840 | AH8: 2140563 | AI8: 430500 | AJ8: 3443777 | AK8: 6653985 | AL8: 4745972 | AM8: 4074521 | AN8: 1515634 | AO8: 1889599 | AP8: 1900919 | AQ8: 735453 | AR8: 420218 | AS8: 8804468 | AT8: 597307 | AU8: 1929384 | AV8: 3303210 | AW8: 7599375 | AX8: 3224730 | AY8: 63041739 | AZ8: 68419367
A11: Sales HYD/Bang
A12: Expected Business | B12: Month
B13: Bangalore | X13: Bangalore Total | Y13: Hyderabad | AZ13: Hyderabad Total | BA13: Grand Total
A14: Status | B14: 45292 | C14: 45323 | D14: 45352 | E14: 45383 | F14: 45413 | G14: 45444 | H14: 45474 | I14: 45505 | J14: 45536 | K14: 45566 | L14: 45597 | M14: 45627 | N14: 45658 | O14: 45689 | P14: 45717 | Q14: 45748 | R14: 45778 | S14: 45809 | T14: 45839 | U14: 45870 | V14: 45901 | W14: 45931 | Y14: 45231 | Z14: 45261 | AA14: 45292 | AB14: 45323 | AC14: 45352 | AD14: 45383 | AE14: 45413 | AF14: 45444 | AG14: 45474 | AH14: 45505 | AI14: 45536 | AJ14: 45566 | AK14: 45597 | AL14: 45627 | AM14: 45658 | AN14: 45689 | AO14: 45717 | AP14: 45748 | AQ14: 45778 | AR14: 45809 | AS14: 45839 | AT14: 45870 | AU14: 45901 | AV14: 45931 | AW14: 45962 | AX14: 45992 | AY14: 46113
A15: Closed(C4) | B15: 244671 | C15: 184184 | D15: 672620 | E15: 630993 | F15: 224623 | G15: 177151 | H15: 357305 | I15: 172060 | J15: 173396 | K15: 36855 | L15: 175565 | M15: 139607 | N15: 158594 | O15: 192091 | P15: 137347 | Q15: 190048 | R15: 246746 | S15: 188839 | T15: 381506 | U15: 430226 | V15: 132965 | W15: 130236 | X15: 5377628 | Y15: 216000 | Z15: 441884 | AA15: 628380 | AB15: 490291 | AC15: 867317 | AD15: 555748 | AE15: 2786000 | AF15: 3048664 | AG15: 597840 | AH15: 2140563 | AI15: 430500 | AJ15: 3443777 | AK15: 6653985 | AL15: 4745972 | AM15: 4074521 | AN15: 1515634 | AO15: 1889599 | AP15: 1900919 | AQ15: 735453 | AR15: 420218 | AS15: 8804468 | AT15: 597307 | AU15: 1929384 | AV15: 3303210 | AW15: 7599375 | AX15: 3224730 | AY15: 0 | AZ15: 63041739 | BA15: 68419367
A16: Negotiation(C2) | B16: 0 | C16: 0 | D16: 0 | E16: 0 | F16: 0 | G16: 0 | H16: 0 | I16: 0 | J16: 0 | K16: 0 | L16: 0 | M16: 0 | N16: 0 | O16: 0 | P16: 0 | Q16: 0 | R16: 0 | S16: 0 | T16: 0 | U16: 0 | V16: 0 | W16: 0 | X16: 0 | Y16: 0 | Z16: 0 | AA16: 0 | AB16: 0 | AC16: 0 | AD16: 0 | AE16: 0 | AF16: 0 | AG16: 0 | AH16: 0 | AI16: 0 | AJ16: 0 | AK16: 0 | AL16: 0 | AM16: 0 | AN16: 0 | AO16: 0 | AP16: 0 | AQ16: 0 | AR16: 0 | AS16: 0 | AT16: 0 | AU16: 0 | AV16: 0 | AW16: 0 | AX16: 0 | AY16: 0 | AZ16: 0 | BA16: 0
A17: Follow-up(C1) | B17: 0 | C17: 0 | D17: 0 | E17: 0 | F17: 0 | G17: 0 | H17: 0 | I17: 0 | J17: 0 | K17: 0 | L17: 0 | M17: 0 | N17: 0 | O17: 0 | P17: 0 | Q17: 0 | R17: 0 | S17: 0 | T17: 0 | U17: 0 | V17: 0 | W17: 0 | X17: 0 | Y17: 0 | Z17: 0 | AA17: 0 | AB17: 0 | AC17: 0 | AD17: 0 | AE17: 0 | AF17: 0 | AG17: 0 | AH17: 0 | AI17: 0 | AJ17: 0 | AK17: 0 | AL17: 0 | AM17: 0 | AN17: 0 | AO17: 0 | AP17: 0 | AQ17: 0 | AR17: 0 | AS17: 0 | AT17: 0 | AU17: 0 | AV17: 0 | AW17: 0 | AX17: 0 | AY17: 0 | AZ17: 0 | BA17: 0
A18: Introduction(C0) | B18: 0 | C18: 0 | D18: 0 | E18: 0 | F18: 0 | G18: 0 | H18: 0 | I18: 0 | J18: 0 | K18: 0 | L18: 0 | M18: 0 | N18: 0 | O18: 0 | P18: 0 | Q18: 0 | R18: 0 | S18: 0 | T18: 0 | U18: 0 | V18: 0 | W18: 0 | X18: 0 | Y18: 0 | Z18: 0 | AA18: 0 | AB18: 0 | AC18: 0 | AD18: 0 | AE18: 0 | AF18: 0 | AG18: 0 | AH18: 0 | AI18: 0 | AJ18: 0 | AK18: 0 | AL18: 0 | AM18: 0 | AN18: 0 | AO18: 0 | AP18: 0 | AQ18: 0 | AR18: 0 | AS18: 0 | AT18: 0 | AU18: 0 | AV18: 0 | AW18: 0 | AX18: 0 | AY18: 0 | AZ18: 0 | BA18: 0
A19: Grand Total | B19: 244671 | C19: 184184 | D19: 672620 | E19: 630993 | F19: 224623 | G19: 177151 | H19: 357305 | I19: 172060 | J19: 173396 | K19: 36855 | L19: 175565 | M19: 139607 | N19: 158594 | O19: 192091 | P19: 137347 | Q19: 190048 | R19: 246746 | S19: 188839 | T19: 381506 | U19: 430226 | V19: 132965 | W19: 130236 | X19: 5377628 | Y19: 216000 | Z19: 441884 | AA19: 628380 | AB19: 490291 | AC19: 867317 | AD19: 555748 | AE19: 2786000 | AF19: 3048664 | AG19: 597840 | AH19: 2140563 | AI19: 430500 | AJ19: 3443777 | AK19: 6653985 | AL19: 4745972 | AM19: 4074521 | AN19: 1515634 | AO19: 1889599 | AP19: 1900919 | AQ19: 735453 | AR19: 420218 | AS19: 8804468 | AT19: 597307 | AU19: 1929384 | AV19: 3303210 | AW19: 7599375 | AX19: 3224730 | AY19: 0 | AZ19: 63041739 | BA19: 68419367
A21: Overall Sales Accounts
A22: Count of A/C Name | B22: Month
A23: Status | B23: 45231 | C23: 45261 | D23: 45292 | E23: 45323 | F23: 45352 | G23: 45383 | H23: 45413 | I23: 45444 | J23: 45474 | K23: 45505 | L23: 45536 | M23: 45566 | N23: 45597 | O23: 45627 | P23: 45658 | Q23: 45689 | R23: 45717 | S23: 45748 | T23: 45778 | U23: 45809 | V23: 45839 | W23: 45870 | X23: 45901 | Y23: 45931 | Z23: Grand Total
A24: Closed(C4) | B24: 1 | C24: 16 | D24: 35 | E24: 18 | F24: 75 | G24: 77 | H24: 27 | I24: 35 | J24: 19 | K24: 22 | L24: 28 | M24: 48 | N24: 27 | O24: 55 | P24: 62 | Q24: 70 | R24: 104 | S24: 43 | T24: 36 | U24: 33 | V24: 33 | W24: 44 | X24: 74 | Y24: 58 | Z24: 1040
A25: Negotiation(C2) | B25: 0 | C25: 0 | D25: 0 | E25: 0 | F25: 0 | G25: 0 | H25: 0 | I25: 0 | J25: 0 | K25: 0 | L25: 0 | M25: 0 | N25: 0 | O25: 0 | P25: 0 | Q25: 0 | R25: 0 | S25: 0 | T25: 0 | U25: 0 | V25: 0 | W25: 0 | X25: 2 | Y25: 0 | Z25: 2
A26: Grand Total | B26: 1 | C26: 16 | D26: 35 | E26: 18 | F26: 75 | G26: 77 | H26: 27 | I26: 35 | J26: 19 | K26: 22 | L26: 28 | M26: 48 | N26: 27 | O26: 55 | P26: 62 | Q26: 70 | R26: 104 | S26: 43 | T26: 36 | U26: 33 | V26: 33 | W26: 44 | X26: 76 | Y26: 58 | Z26: 1042
A32: Overall Sales Amount
A33: Sum of Expected Business | B33: Month
A34: Status | B34: 45231 | C34: 45261 | D34: 45292 | E34: 45323 | F34: 45352 | G34: 45383 | H34: 45413 | I34: 45444 | J34: 45474 | K34: 45505 | L34: 45536 | M34: 45566 | N34: 45597 | O34: 45627 | P34: 45658 | Q34: 45689 | R34: 45717 | S34: 45748 | T34: 45778 | U34: 45809 | V34: 45839 | W34: 45870 | X34: 45901 | Y34: 45931 | Z34: 45962 | AA34: 45992 | AB34: 46023 | AC34: 46054 | AD34: 46082 | AE34: 46113 | AF34: Grand Total
A35: Closed(C4) | B35: 216000 | C35: 441884 | D35: 873051 | E35: 674475 | F35: 1539937 | G35: 1186741 | H35: 3010623 | I35: 3225815 | J35: 955145 | K35: 2312623 | L35: 603896 | M35: 3480632 | N35: 6829550 | O35: 4885579 | P35: 4233115 | Q35: 1707725 | R35: 2026946 | S35: 2090967 | T35: 982199 | U35: 609057 | V35: 9185974 | W35: 1027533 | X35: 2062349 | Y35: 3566088 | Z35: 10397807 | AA35: 5355260 | AB35: 2718533 | AC35: 2380989 | AD35: 4453267 | AE35: 2925637 | AF35: 85959397
A36: Negotiation(C2) | B36: 0 | C36: 0 | D36: 0 | E36: 0 | F36: 0 | G36: 0 | H36: 0 | I36: 0 | J36: 0 | K36: 0 | L36: 0 | M36: 0 | N36: 0 | O36: 0 | P36: 0 | Q36: 0 | R36: 0 | S36: 0 | T36: 0 | U36: 0 | V36: 0 | W36: 0 | X36: 0 | Y36: 0 | Z36: 0 | AA36: 0 | AB36: 0 | AC36: 0 | AD36: 0 | AE36: 1000000 | AF36: 1000000
A37: Follow-up(C1) | B37: 0 | C37: 0 | D37: 0 | E37: 0 | F37: 0 | G37: 0 | H37: 0 | I37: 0 | J37: 0 | K37: 0 | L37: 0 | M37: 0 | N37: 0 | O37: 0 | P37: 0 | Q37: 0 | R37: 0 | S37: 0 | T37: 0 | U37: 0 | V37: 0 | W37: 0 | X37: 0 | Y37: 0 | Z37: 0 | AA37: 0 | AB37: 0 | AC37: 0 | AD37: 0 | AE37: 765000 | AF37: 765000
A38: Introduction(C0) | B38: 0 | C38: 0 | D38: 0 | E38: 0 | F38: 0 | G38: 0 | H38: 0 | I38: 0 | J38: 0 | K38: 0 | L38: 0 | M38: 0 | N38: 0 | O38: 0 | P38: 0 | Q38: 0 | R38: 0 | S38: 0 | T38: 0 | U38: 0 | V38: 0 | W38: 0 | X38: 0 | Y38: 0 | Z38: 0 | AA38: 0 | AB38: 0 | AC38: 0 | AD38: 0 | AE38: 365000 | AF38: 365000
A39: Grand Total | B39: 216000 | C39: 441884 | D39: 873051 | E39: 674475 | F39: 1539937 | G39: 1186741 | H39: 3010623 | I39: 3225815 | J39: 955145 | K39: 2312623 | L39: 603896 | M39: 3480632 | N39: 6829550 | O39: 4885579 | P39: 4233115 | Q39: 1707725 | R39: 2026946 | S39: 2090967 | T39: 982199 | U39: 609057 | V39: 9185974 | W39: 1027533 | X39: 2062349 | Y39: 3566088 | Z39: 10397807 | AA39: 5355260 | AB39: 2718533 | AC39: 2380989 | AD39: 4453267 | AE39: 5055637 | AF39: 88089397
A42: Sales Current Quarter | I42: TARGET
A43: Sum of Expected Business | B43: Month | H43: Jan | I43: Feb | J43: March | K43: April | U43: =TODAY()-1 -> 46293
A44: Status | B44: 46023 | C44: 46054 | D44: 46082 | E44: 46113 | F44: Grand Total | H44: 1655248 | I44: 1639140 | J44: 1547632 | K44: 1547632 | S44: 45931 | T44: Target ADS | U44: Actual ADS | V44: Required ADS
A45: Closed(C4) | B45: 2718533 | C45: 2380989 | D45: 4453267 | E45: 2925637 | F45: 12478426 | T45: =1725000/31 -> 55645.161 | U45: =I45/($U$43-$S$44) -> 0 | V45: =T45+T45-U45 -> 111290.32
A46: Negotiation(C2) | B46: 0 | C46: 0 | D46: 0 | E46: 1000000 | F46: 1000000
A47: Follow-up(C1) | B47: 0 | C47: 0 | D47: 0 | E47: 765000 | F47: 765000 | S47: =1700000/31 -> 54838.71
A48: Introduction(C0) | B48: 0 | C48: 0 | D48: 0 | E48: 365000 | F48: 365000 | S48: =J45/7 -> 0
A49: Grand Total | B49: 2718533 | C49: 2380989 | D49: 4453267 | E49: 5055637 | F49: 14608426 | S49: =S48/S47 -> 0
U50: =U45/($H$50/31) -> #DIV/0!
A53: Expected sales of Haleem | B53: Month
...

Sheet DCR
A1: Date | B1: A/C Name | C1: Connect Status | D1: TYPE | E1: Industry | F1: Spoc Name | G1: Conversation | H1: Expected Business | I1: Actual Closed Business | J1: Expected Business Month | K1: Region | L1: Status | M1: Lead Status | N1: Reason | O1: Expected sales of Haleem | P1: Type Of Business | Q1: Punched Date | R1: 1st meeting Date | S1: Month | T1: Week | U1: Year
A2: 45238 | B2: Turning Minds | C2: Call | D2: Corporate | E2: IT | F2: Sairam | G2: Shared details about bulk booking | H2: 20000 | I2: 0 | J2: 45383 | K2: Hyderabad | L2: Cancelled | M2: Cancelled | N2: No requirement | S2: =TEXT(Table1[[#This Row],[Date]],"MMM-YY") -> Nov-23 | T2: =_xlfn.ISOWEEKNUM(Table1[[#This Row],[Date]]) -> 45 | U2: =TEXT(Table1[[#This Row],[Expected Business Month]],"YYYY") -> 2024 | W2: Introduction(C0)
A3: 45238 | B3: Computer Generated Solutions PVT LTD | C3: Call | D3: Corporate | E3: IT | F3: Madhvi | G3: Shared details about bulk booking | H3: 10000 | I3: 0 | J3: 45383 | K3: Hyderabad | L3: Cancelled | M3: Cancelled | N3: No requirement | O3: 0 | S3: =TEXT(Table1[[#This Row],[Date]],"MMM-YY") -> Nov-23 | T3: =_xlfn.ISOWEEKNUM(Table1[[#This Row],[Date]]) -> 45 | U3: =TEXT(Table1[[#This Row],[Expected Business Month]],"YYYY") -> 2024 | W3: Follow-up(C1)
A4: 45238 | B4: Newyork Global | C4: Call | D4: Corporate | E4: IT | F4: Ugesh | G4: Shared details about bulk booking | H4: 20000 | I4: 0 | J4: 45383 | K4: Hyderabad | L4: Cancelled | M4: Cancelled | N4: No requirement | S4: =TEXT(Table1[[#This Row],[Date]],"MMM-YY") -> Nov-23 | T4: =_xlfn.ISOWEEKNUM(Table1[[#This Row],[Date]]) -> 45 | U4: =TEXT(Table1[[#This Row],[Expected Business Month]],"YYYY") -> 2024 | W4: Negotiation(C2)
A5: 45246 | B5: Splash Entertainments | C5: F2F | D5: Events | E5: Tourism | F5: Ghouse | G5: Shared proposal for discount on Bulk Orders for travelling students. | H5: 100000 | I5: 0 | J5: 45292 | K5: Hyderabad | L5: Cancelled | M5: Cancelled | N5: Less budget of students | S5: =TEXT(Table1[[#This Row],[Date]],"MMM-YY") -> Nov-23 | T5: =_xlfn.ISOWEEKNUM(Table1[[#This Row],[Date]]) -> 46 | U5: =TEXT(Table1[[#This Row],[Expected Business Month]],"YYYY") -> 2024 | W5: Confirmed(C3)
A6: 45250 | B6: NextSphere Technology | C6: Call | D6: Corporate | E6: IT | F6: Meenakshi | G6: Shaired details about bulk booking and ODC | H6: 12000 | I6: 0 | J6: 45383 | K6: Hyderabad | L6: Cancelled | M6: Cancelled | N6: No requirement | S6: =TEXT(Table1[[#This Row],[Date]],"MMM-YY") -> Nov-23 | T6: =_xlfn.ISOWEEKNUM(Table1[[#This Row],[Date]]) -> 47 | U6: =TEXT(Table1[[#This Row],[Expected Business Month]],"YYYY") -> 2024 | W6: Closed(C4)
A7: 45250 | B7: Fiserve | C7: Call | D7: Corporate | E7: IT | F7: Saran (Admin) | G7: Shared details about Bulk orders | H7: 100000 | I7: 0 | J7: 45292 | K7: Hyderabad | L7: Cancelled | M7: Cancelled | N7: Event Cancelled | S7: =TEXT(Table1[[#This Row],[Date]],"MMM-YY") -> Nov-23 | T7: =_xlfn.ISOWEEKNUM(Table1[[#This Row],[Date]]) -> 47 | U7: =TEXT(Table1[[#This Row],[Expected Business Month]],"YYYY") -> 2024 | W7: Cancelled
A8: 45253 | B8: Fiserve | C8: Call | D8: Corporate | E8: IT | F8: Sameena | G8: Shaired details about bulk booking and ODC | H8: 7000 | I8: 0 | J8: 45292 | K8: Hyderabad | L8: Cancelled | M8: Cancelled | N8: Event Cancelled | S8: =TEXT(Table1[[#This Row],[Date]],"MMM-YY") -> Nov-23 | T8: =_xlfn.ISOWEEKNUM(Table1[[#This Row],[Date]]) -> 47 | U8: =TEXT(Table1[[#This Row],[Expected Business Month]],"YYYY") -> 2024
A9: 45253 | B9: Hyderabad Metro Rail LTD | C9: F2F | D9: Corporate | E9: Transport | F9: Sulakshna Shukla ( Admin Head) | G9: Duiscussed Bulk Order, they want Bakery counter at their office | H9: 5000 | I9: 5000 | J9: 45292 | K9: Hyderabad | L9: Closed(C4) | M9: Closed | R9: 45253 | S9: =TEXT(Table1[[#This Row],[Date]],"MMM-YY") -> Nov-23 | T9: =_xlfn.ISOWEEKNUM(Table1[[#This Row],[Date]]) -> 47 | U9: =TEXT(Table1[[#This Row],[Expected Business Month]],"YYYY") -> 2024
A10: 45254 | B10: Stumag | C10: F2F | D10: College | E10: Events | F10: Pooja | G10: Event on 12 Dec 2023 Looking for sponsorship | H10: 0 | I10: 0 | J10: 45292 | K10: Hyderabad | L10: Cancelled | M10: Cancelled | N10: Charging 50,000 and very less potential event | S10: =TEXT(Table1[[#This Row],[Date]],"MMM-YY") -> Nov-23 | T10: =_xlfn.ISOWEEKNUM(Table1[[#This Row],[Date]]) -> 47 | U10: =TEXT(Table1[[#This Row],[Expected Business Month]],"YYYY") -> 2024
A11: 45254 | B11: Express Events | C11: F2F | D11: Events | E11: Events | F11: Avinash Bharadwaj | G11: Cancelled as they were charging 50,000 + GST which was not profitable | H11: 100000 | I11: 0 | J11: 45261 | K11: Hyderabad | L11: Cancelled | M11: Cancelled | N11: Dropped as not profitable event | S11: =TEXT(Table1[[#This Row],[Date]],"MMM-YY") -> Nov-23 | T11: =_xlfn.ISOWEEKNUM(Table1[[#This Row],[Date]]) -> 47 | U11: =TEXT(Table1[[#This Row],[Expected Business Month]],"YYYY") -> 2023
A12: 45256 | B12: SIP Event at Shamshabad | C12: F2F | D12: Events | E12: Education | F12: Arun | G12: Participated in Event with 12000 footfall | H12: 216000 | I12: 216000 | J12: 45231 | K12: Hyderabad | L12: Closed(C4) | M12: Closed | S12: =TEXT(Table1[[#This Row],[Date]],"MMM-YY") -> Nov-23 | T12: =_xlfn.ISOWEEKNUM(Table1[[#This Row],[Date]]) -> 47 | U12: =TEXT(Table1[[#This Row],[Expected Business Month]],"YYYY") -> 2023
A13: 45257 | B13: GGR International School | C13: F2F | D13: School | E13: Education | F13: Jyotsna ( Principal) | G13: Shared details for bulk orders and school event. | H13: 10000 | I13: 0 | J13: 45383 | K13: Hyderabad | L13: Cancelled | M13: Cancelled | N13: No requirement | S13: =TEXT(Table1[[#This Row],[Date]],"MMM-YY") -> Nov-23 | T13: =_xlfn.ISOWEEKNUM(Table1[[#This Row],[Date]]) -> 48 | U13: =TEXT(Table1[[#This Row],[Expected Business Month]],"YYYY") -> 2024
A14: 45257 | B14: Bijli Rides | C14: F2F | D14: Corporate | E14: Transport | F14: Shivam Sisodia (MD) | G14: Shared details about our offerings, will plan for team lunch. | H14: 3000 | I14: 0 | J14: 45383 | K14: Hyderabad | L14: Cancelled | M14: Cancelled | N14: No requirement | S14: =TEXT(Table1[[#This Row],[Date]],"MMM-YY") -> Nov-23 | T14: =_xlfn.ISOWEEKNUM(Table1[[#This Row],[Date]]) -> 48 | U14: =TEXT(Table1[[#This Row],[Expected Business Month]],"YYYY") -> 2024
A15: 45257 | B15: Infinity Holidays | C15: F2F | D15: Events | E15: Events | F15: Vikas | G15: Shared proposal for discount on Bulk Orders for travelling students. | H15: 10000 | I15: 0 | J15: 45292 | K15: Hyderabad | L15: Cancelled | M15: Cancelled | N15: Dropped as less budget of students | S15: =TEXT(Table1[[#This Row],[Date]],"MMM-YY") -> Nov-23 | T15: =_xlfn.ISOWEEKNUM(Table1[[#This Row],[Date]]) -> 48 | U15: =TEXT(Table1[[#This Row],[Expected Business Month]],"YYYY") -> 2024
A16: 45258 | B16: Alliance Pro IT | C16: F2F | D16: Corporate | E16: IT | F16: Mrudula ( HR & Admin) | G16: They will plan for team lunch and bulk orders | H16: 10000 | I16: 0 | J16: 45474 | K16: Hyderabad | L16: Cancelled | M16: Cancelled | N16: Event Cancelled | S16: =TEXT(Table1[[#This Row],[Date]],"MMM-YY") -> Nov-23 | T16: =_xlfn.ISOWEEKNUM(Table1[[#This Row],[Date]]) -> 48 | U16: =TEXT(Table1[[#This Row],[Expected Business Month]],"YYYY") -> 2024
A17: 45258 | B17: Delta Technologies | C17: F2F | D17: Corporate | E17: IT | F17: Amit ( Head HR) | G17: Introduction of our products and offerings, Need to meet Admin head shortly for Annual function and bulk orders | H17: 10000 | I17: 0 | J17: 45474 | K17: Hyderabad | L17: Cancelled | M17: Cancelled | N17: No requirement | S17: =TEXT(Table1[[#This Row],[Date]],"MMM-YY") -> Nov-23 | T17: =_xlfn.ISOWEEKNUM(Table1[[#This Row],[Date]]) -> 48 | U17: =TEXT(Table1[[#This Row],[Expected Business Month]],"YYYY") -> 2024
A18: 45258 | B18: Puneria Events | C18: Call | D18: Corporate | E18: Events | F18: Sandeep (MD) | G18: Shared introduction about Bulk order and ODC | H18: 5000 | I18: 0 | J18: 45383 | K18: Hyderabad | L18: Cancelled | M18: Cancelled | N18: No requirement | S18: =TEXT(Table1[[#This Row],[Date]],"MMM-YY") -> Nov-23 | T18: =_xlfn.ISOWEEKNUM(Table1[[#This Row],[Date]]) -> 48 | U18: =TEXT(Table1[[#This Row],[Expected Business Month]],"YYYY") -> 2024
A19: 45258 | B19: Shankar Agencies | C19: Call | D19: Events | E19: Events | F19: Shankar | G19: Shared proposal for discount on Bulk Orders for travelling students. | H19: 30000 | I19: 0 | J19: 45292 | K19: Hyderabad | L19: Cancelled | M19: Cancelled | N19: Less budget of travelling students | S19: =TEXT(Table1[[#This Row],[Date]],"MMM-YY") -> Nov-23 | T19: =_xlfn.ISOWEEKNUM(Table1[[#This Row],[Date]]) -> 48 | U19: =TEXT(Table1[[#This Row],[Expected Business Month]],"YYYY") -> 2024
A20: 45259 | B20: Tashee Linux | C20: F2F | D20: Corporate | E20: IT | F20: Anita Baranwal (HR) | G20: Introduction of our products for bulk orders | H20: 8000 | I20: 0 | J20: 45474 | K20: Hyderabad | L20: Cancelled | M20: Cancelled | N20: No requirement | S20: =TEXT(Table1[[#This Row],[Date]],"MMM-YY") -> Nov-23 | T20: =_xlfn.ISOWEEKNUM(Table1[[#This Row],[Date]]) -> 48 | U20: =TEXT(Table1[[#This Row],[Expected Business Month]],"YYYY") -> 2024
A21: 45259 | B21: Celon Labs | C21: F2F | D21: Corporate | E21: Pharma | F21: Gulab Singh Rajput (GM HR) | G21: Shared corporate offerings | H21: 10000 | I21: 0 | J21: 45474 | K21: Hyderabad | L21: Cancelled | M21: Cancelled | N21: No requirement | S21: =TEXT(Table1[[#This Row],[Date]],"MMM-YY") -> Nov-23 | T21: =_xlfn.ISOWEEKNUM(Table1[[#This Row],[Date]]) -> 48 | U21: =TEXT(Table1[[#This Row],[Expected Business Month]],"YYYY") -> 2024
A22: 45260 | B22: National Manpower | C22: Call | D22: Corporate | E22: IT | F22: Swamy | G22: Discoussed about bulk food delevery at events | H22: 8000 | I22: 0 | J22: 45352 | K22: Hyderabad | L22: Cancelled | M22: Cancelled | N22: Preparing their own food | S22: =TEXT(Table1[[#This Row],[Date]],"MMM-YY") -> Nov-23 | T22: =_xlfn.ISOWEEKNUM(Table1[[#This Row],[Date]]) -> 48 | U22: =TEXT(Table1[[#This Row],[Expected Business Month]],"YYYY") -> 2024
A23: 45260 | B23: Capgemini | C23: Call | D23: Corporate | E23: IT | F23: Amol | G23: Dine in of 25 capgemini employees on 13 Dec 2023 | H23: 13200 | I23: 13200 | J23: 45261 | K23: Hyderabad | L23: Closed(C4) | M23: Closed | S23: =TEXT(Table1[[#This Row],[Date]],"MMM-YY") -> Nov-23 | T23: =_xlfn.ISOWEEKNUM(Table1[[#This Row],[Date]]) -> 48 | U23: =TEXT(Table1[[#This Row],[Expected Business Month]],"YYYY") -> 2023
A24: 45261 | B24: Balaji Agencies | C24: Call | D24: Corporate | E24: Tourism | F24: Venkateshwar | G24: Shared proposal for bulk Biryani orders | H24: 50000 | I24: 0 | J24: 45352 | K24: Hyderabad | L24: Cancelled | M24: Cancelled | N24: Budget constrains for travelling students | S24: =TEXT(Table1[[#This Row],[Date]],"MMM-YY") -> Dec-23 | T24: =_xlfn.ISOWEEKNUM(Table1[[#This Row],[Date]]) -> 48 | U24: =TEXT(Table1[[#This Row],[Expected Business Month]],"YYYY") -> 2024
A25: 45261 | B25: Wonderla | C25: Call | D25: Corporate | E25: Entertainment | F25: Souvik | G25: bulk order of plum cakes they purchased from kochi due to influence of MD | H25: 150000 | I25: 0 | J25: 45261 | K25: Hyderabad | L25: Cancelled | M25: Cancelled | N25: Dropped as they procured inhouse from Kochi | S25: =TEXT(Table1[[#This Row],[Date]],"MMM-YY") -> Dec-23 | T25: =_xlfn.ISOWEEKNUM(Table1[[#This Row],[Date]]) -> 48 | U25: =TEXT(Table1[[#This Row],[Expected Business Month]],"YYYY") -> 2023
A26: 45261 | B26: Medha Servo Drives | C26: Call | D26: Corporate | E26: Manufacturing | F26: Vinay Yadav | G26: Shared details about Bulk orders | H26: 20000 | I26: 0 | J26: 45474 | K26: Hyderabad | L26: Cancelled | M26: Cancelled | N26: No requirement | S26: =TEXT(Table1[[#This Row],[Date]],"MMM-YY") -> Dec-23 | T26: =_xlfn.ISOWEEKNUM(Table1[[#This Row],[Date]]) -> 48 | U26: =TEXT(Table1[[#This Row],[Expected Business Month]],"YYYY") -> 2024
A27: 45261 | B27: St Anns College | C27: F2F | D27: College | E27: Education | F27: Pravalika | G27: Shared details of bulk orders | H27: 0 | I27: 0 | J27: 45261 | K27: Hyderabad | L27: Cancelled | M27: Cancelled | N27: They procured inhouse for Christmas | S27: =TEXT(Table1[[#This Row],[Date]],"MMM-YY") -> Dec-23 | T27: =_xlfn.ISOWEEKNUM(Table1[[#This Row],[Date]]) -> 48 | U27: =TEXT(Table1[[#This Row],[Expected Business Month]],"YYYY") -> 2023
A28: 45264 | B28: OG'S Wonderland Flea | C28: Call | D28: Events | E28: Entertainment | F28: Onegolf | G28: Discussing for participation , event on 24 Dec 2023 | H28: 100000 | I28: 0 | J28: 45261 | K28: Hyderabad | L28: Cancelled | M28: Cancelled | N28: Event Cancelled | S28: =TEXT(Table1[[#This Row],[Date]],"MMM-YY") -> Dec-23 | T28: =_xlfn.ISOWEEKNUM(Table1[[#This Row],[Date]]) -> 49 | U28: =TEXT(Table1[[#This Row],[Expected Business Month]],"YYYY") -> 2023
A29: 45265 | B29: Sunburn | C29: Call | D29: Events | E29: Entertainment | F29: Hitesh | G29: Discussed, This year they have inhouse F&B | H29: 100000 | I29: 0 | J29: 45261 | K29: Hyderabad | L29: Cancelled | M29: Cancelled | N29: F&B Was done inhouse by PUB | S29: =TEXT(Table1[[#This Row],[Date]],"MMM-YY") -> Dec-23 | T29: =_xlfn.ISOWEEKNUM(Table1[[#This Row],[Date]]) -> 49 | U29: =TEXT(Table1[[#This Row],[Expected Business Month]],"YYYY") -> 2023
A30: 45266 | B30: Kirby Building Technology | C30: F2F | D30: Corporate | E30: IT | F30: Naveen | G30: Shared proposal for bulk orders , given first order for 12 Nov 2023 | H30: 5500 | I30: 5500 | J30: 45261 | K30: Hyderabad | L30: Closed(C4) | M30: Closed | S30: =TEXT(Table1[[#This Row],[Date]],"MMM-YY") -> Dec-23 | T30: =_xlfn.ISOWEEKNUM(Table1[[#This Row],[Date]]) -> 49 | U30: =TEXT(Table1[[#This Row],[Expected Business Month]],"YYYY") -> 2023
A31: 45266 | B31: Mooving D Needle | C31: F2F | D31: Corporate | E31: IT | F31: Bhargav | G31: Shared details about discount on bulk orders | H31: 10000 | I31: 0 | J31: 45474 | K31: Hyderabad | L31: Cancelled | M31: Cancelled | N31: No requirement | S31: =TEXT(Table1[[#This Row],[Date]],"MMM-YY") -> Dec-23 | T31: =_xlfn.ISOWEEKNUM(Table1[[#This Row],[Date]]) -> 49 | U31: =TEXT(Table1[[#This Row],[Expected Business Month]],"YYYY") -> 2024
A32: 45266 | B32: Granules India Limited | C32: F2F | D32: Corporate | E32: Pharma | F32: Uma Rao (CHRO) | G32: Shared details for bulk food deliveries for their Factory Unit | H32: 20000 | I32: 0 | J32: 45474 | K32: Hyderabad | L32: Cancelled | M32: Cancelled | N32: No Budget | S32: =TEXT(Table1[[#This Row],[Date]],"MMM-YY") -> Dec-23 | T32: =_xlfn.ISOWEEKNUM(Table1[[#This Row],[Date]]) -> 49 | U32: =TEXT(Table1[[#This Row],[Expected Business Month]],"YYYY") -> 2024
A33: 45266 | B33: St Anns College | C33: F2F | D33: College | E33: Education | F33: Mounika | G33: event on 21 & 22 Dec 2023 | H33: 80000 | I33: 0 | J33: 45261 | K33: Hyderabad | L33: Cancelled | M33: Cancelled | N33: Dropped due to less potential | R33: 45261 | S33: =TEXT(Table1[[#This Row],[Date]],"MMM-YY") -> Dec-23 | T33: =_xlfn.ISOWEEKNUM(Table1[[#This Row],[Date]]) -> 49 | U33: =TEXT(Table1[[#This Row],[Expected Business Month]],"YYYY") -> 2023
A34: 45267 | B34: TCS | C34: Call | D34: Corporate | E34: IT | F34: Nimesh Verma (Admin) | G34: Shared introduction given appointment on Monday | H34: 15000 | I34: 0 | J34: 45444 | K34: Hyderabad | L34: Cancelled | M34: Cancelled | S34: =TEXT(Table1[[#This Row],[Date]],"MMM-YY") -> Dec-23 | T34: =_xlfn.ISOWEEKNUM(Table1[[#This Row],[Date]]) -> 49 | U34: =TEXT(Table1[[#This Row],[Expected Business Month]],"YYYY") -> 2024
A35: 45267 | B35: Novartis | C35: Call | D35: Corporate | E35: Pharma | F35: Sneha Mamidwar (Admin) | G35: Shared introduction given appointment on | H35: 20000 | I35: 0 | J35: 45474 | K35: Hyderabad | L35: Cancelled | M35: Cancelled | N35: Event Cancelled | S35: =TEXT(Table1[[#This Row],[Date]],"MMM-YY") -> Dec-23 | T35: =_xlfn.ISOWEEKNUM(Table1[[#This Row],[Date]]) -> 49 | U35: =TEXT(Table1[[#This Row],[Expected Business Month]],"YYYY") -> 2024
A36: 45267 | B36: Glam Parikrama Event | C36: F2F | D36: Events | E36: Events | F36: Lalitha George (Founder) | G36: Done reckey for event on 8th & 9 Dec 2023 | H36: 24000 | I36: 24000 | J36: 45261 | K36: Hyderabad | L36: Closed(C4) | M36: Closed | S36: =TEXT(Table1[[#This Row],[Date]],"MMM-YY") -> Dec-23 | T36: =_xlfn.ISOWEEKNUM(Table1[[#This Row],[Date]]) -> 49 | U36: =TEXT(Table1[[#This Row],[Expected Business Month]],"YYYY") -> 2023
A37: 45268 | B37: St Mathews Church | C37: F2F | D37: Christmas | E37: Community | F37: Sabitha | G37: Shared Bakery menu | H37: 10000 | I37: 0 | J37: 45383 | K37: Hyderabad | L37: Cancelled | M37: Cancelled | N37: They procured inhouse for Christmas | S37: =TEXT(Table1[[#This Row],[Date]],"MMM-YY") -> Dec-23 | T37: =_xlfn.ISOWEEKNUM(Table1[[#This Row],[Date]]) -> 49 | U37: =TEXT(Table1[[#This Row],[Expected Business Month]],"YYYY") -> 2024
A38: 45271 | B38: Aakruti School | C38: F2F | D38: Corporate | E38: IT | F38: Sarika | G38: Shared introduction about Bulk order and ODC | H38: 20000 | I38: 0 | J38: 45474 | K38: Hyderabad | L38: Cancelled | M38: Cancelled | N38: Event Cancelled | S38: =TEXT(Table1[[#This Row],[Date]],"MMM-YY") -> Dec-23 | T38: =_xlfn.ISOWEEKNUM(Table1[[#This Row],[Date]]) -> 50 | U38: =TEXT(Table1[[#This Row],[Expected Business Month]],"YYYY") -> 2024
A39: 45272 | B39: EGHM Church | C39: F2F | D39: Events | E39: Community | F39: Hema | G39: Introduction about bulk orders and bakery items | H39: 10000 | I39: 10000 | J39: 45292 | K39: Hyderabad | L39: Closed(C4) | M39: Closed | N39: They purchased from Heritage Branch | S39: =TEXT(Table1[[#This Row],[Date]],"MMM-YY") -> Dec-23 | T39: =_xlfn.ISOWEEKNUM(Table1[[#This Row],[Date]]) -> 50 | U39: =TEXT(Table1[[#This Row],[Expected Business Month]],"YYYY") -> 2024
A40: 45272 | B40: Mirackles & Testimony Church | C40: Call | D40: Events | E40: Community | F40: Rahul | G40: Introduction about bulk orders and bakery items | H40: 8000 | I40: 0 | J40: 45292 | K40: Hyderabad | L40: Cancelled | M40: Cancelled | N40: They Have low budget | S40: =TEXT(Table1[[#This Row],[Date]],"MMM-YY") -> Dec-23 | T40: =_xlfn.ISOWEEKNUM(Table1[[#This Row],[Date]]) -> 50 | U40: =TEXT(Table1[[#This Row],[Expected Business Month]],"YYYY") -> 2024
...

Sheet YLY-QLY Sales
F2: YEARLY SALES
E3: FY 2023 | F3: FY 2024 | G3: FY 2025
D4: Overall Sales | E4: Nov 2023 to March 2024 | F4: April 2024 to March 2025 | G4: April 2025 till Now
D5: Expected Business | H5: Grand Total
D6: Status
D7: Introduction/Co | E7: =SUM('Overall Sales'!B24:F24) -> 145 | F7: =SUM('Overall Sales'!G24:R24) -> 574 | G7: 0 | H7: =GETPIVOTDATA("Expected Business",'Overall Sales'!$A$22,"Status","Introduction/C0") -> #REF!
D8: Followup/C1 | E8: 0 | F8: 0 | G8: 0 | H8: =GETPIVOTDATA("Expected Business",'Overall Sales'!$A$22,"Status","Followup/C1") -> #REF!
D9: Negotiation/C2 | E9: 0 | F9: 0 | G9: 0 | H9: =GETPIVOTDATA("Expected Business",'Overall Sales'!$A$22,"Status","Negotiation/C2") -> #REF!
D10: Confirmed/C3 | E10: 0 | F10: 0 | G10: 0 | H10: =GETPIVOTDATA("Expected Business",'Overall Sales'!$A$22,"Status","Confirmed/C3") -> #REF!
D11: Closed/C4 | E11: =SUM('Overall Sales'!B28:F28) -> 0 | F11: =SUM('Overall Sales'!G28:R28) -> 0 | G11: =SUM('Overall Sales'!S28:V28) -> 0 | H11: =SUM(E11:G11) -> 0
D12: Total | H12: =GETPIVOTDATA("Expected Business",'Overall Sales'!$A$22) -> #REF!
F16: QUARTERLY SALES
E17: FY 2023 | G17: FY 2024 | K17: FY 2025
D18: Overall Sales | E18: Q3 November, December | F18: Q4 | G18: Q1 | H18: Q2 | I18: Q3 | J18: Q4 | K18: Q1 | L18: Q2 | M18: Q3 | N18: Q4 | O18: Grand Total
D19: Expected Business
D20: Status
D21: Introduction/Co | O21: =H7 -> #REF!
D22: Followup/C1 | O22: =H8 -> #REF!
D23: Negotiation/C2 | O23: =H9 -> #REF!
D24: Confirmed/C3 | O24: =H10 -> #REF!
D25: Closed | E25: =SUM('Overall Sales'!B28:C28) -> 0 | F25: =SUM('Overall Sales'!D28:F28) -> 0 | G25: =SUM('Overall Sales'!G28:I28) -> 0 | H25: =SUM('Overall Sales'!J28:L28) -> 0 | I25: =SUM('Overall Sales'!M28:O28) -> 0 | J25: =SUM('Overall Sales'!P28:R28) -> 0 | K25: =SUM('Overall Sales'!S28:U28) -> 0 | L25: =SUM('Overall Sales'!V28:W28) -> 0 | O25: =H11 -> 0
D26: Total | O26: =GETPIVOTDATA("Expected Business",'Overall Sales'!$A$22) -> #REF!

Sheet Key Accounts
B3: Accounts | C3: Sum of Closed Business
B4: Aurobindo Prarma | C4: 238000
B5: Azad Engineering | C5: 2179000
B6: BHEL Church | C6: 151500
B7: Bits Pilani | C7: 46271
B8: Bits Pilani Eid Dinner | C8: 58565
B9: Bits Pilani Perl Fest | C9: 41750
B10: Buffet Dinner at Rajbhavan | C10: 210000
B11: Bulk Delivery at Aurobindo premier League | C11: 292500
B12: Bulk Food order at Kukatpally | C12: 38589
B13: Bulk Order at Nellore for TDP Party Meeting | C13: 111833
B14: Capital Land Ataria/Gokhana | C14: 50000
B15: Cognizant Technology Solutions | C15: 43000
... B87: Zomato | C87: 557702
B88: Grand Total | C88: =SUM(C4:C87) -> 34546060
